Workbook
Name SegmentaciónDeDatos_campaña2: #N/A
Name SegmentaciónDeDatos_cola: #N/A
Name SegmentaciónDeDatos_Crm: #N/A
Name SegmentaciónDeDatos_Direccion2: #N/A
Name SegmentaciónDeDatos_fecha_real: #N/A
Name SegmentaciónDeDatos_fecha_real2: #N/A

Sheet info
A1: fecha real | B1: Linea | C1: Direccion | D1: campaña | E1: Conexión | F1: Crm | G1: cola | H1: hora de contacta | I1: Matriculado | J1: Fecha | K1: Id. llamada | L1: Dispositivo | M1: Servidor | N1: Placa | O1: Slot | P1: Aplicación | Q1: Id. Aplicación | R1: Usuario | S1: Cola | T1: Estado | U1: Sub-Estado | V1: Inicio | W1: Conexión | X1: Fin | Y1: DNIS | Z1: ANI/Teléfono | AA1: Dirección | AB1: Tipo Grabación | AC1: Grabación | AD1: Grabación Depurada | AE1: Tipo | AF1: País/Provincia | AG1: Ciudad/Localidad | AH1: Costo | AI1: Precio | AJ1: Importe Costo | AK1: Importe Precio | AL1: Proveedor | AM1: Detalle | AN1: Duración | AO1: TIPO_DISCADOR | AP1: CRM | AQ1: Base | AR1: Id. Contacto | AS1: Datos | AT1: Log | AU1: Sub-Partes
A2: =+CONCATENATE(DAY(V2),"/",MONTH(V2),"/",YEAR(V2),"")*1 -> 46146 | B2: =+Z2*1 -> 3543319994 | C2: =+AA2 -> ENTRANTE | D2: =VLOOKUP(Q2,Code!E:F,2,0) -> Admisiones | E2: Conectadas | F2: =+AP2 -> 37 | G2: =+S2 -> 26 | H2: =+HOUR(V2) -> 9 | I2: =IFERROR(VLOOKUP(B2,MATRICULAS!A:B,2,0),0)*1 -> 0 | J2: 20260504 | K2: 149043905 | L2: SERVICIOS_SIP | M2: NEO1 | N2: 0 | O2: 0 | P2: CAMPAÑA | Q2: 150 | R2: 8861 - Caceres, Martina | S2: 26 | T2: ANSWER | U2: AGENT | V2: 46146.382 | W2: 46146.382 | X2: 46146.384 | Y2: 01152741410 | Z2: 3543319994 | AA2: ENTRANTE | AB2: FULL | AC2: 3543319994-149043905-20260504090926.mp3 | AE2: NAC-FIJO | AF2: CORDOBA | AG2: ARGÜELLO | AH2: 0 | AI2: 0 | AJ2: 0 | AK2: 0 | AL2: BL | AM2: 3 | AN2: 182 | AO2: NotSet | AP2: 37 | AQ2: 1 | AR2: 2486505 | AT2: |0||SIP/SERVICIOS_SIP-00000ad8|1777896600.2781|16:Normal Clearing|16:PBX|4||-1|NotSet|
A3: =+CONCATENATE(DAY(V3),"/",MONTH(V3),"/",YEAR(V3),"")*1 -> 46146 | B3: =+Z3*1 -> 2994621296 | C3: =+AA3 -> ENTRANTE | D3: =VLOOKUP(Q3,Code!E:F,2,0) -> Admisiones | E3: Conectadas | F3: =+AP3 -> 37 | G3: =+S3 -> 26 | H3: =+HOUR(V3) -> 9 | I3: =IFERROR(VLOOKUP(B3,MATRICULAS!A:B,2,0),0)*1 -> 0 | J3: 20260504 | K3: 149044343 | L3: SERVICIOS_SIP | M3: NEO1 | N3: 0 | O3: 0 | P3: CAMPAÑA | Q3: 150 | R3: 8861 - Caceres, Martina | S3: 26 | T3: ANSWER | U3: AGENT | V3: 46146.397 | W3: 46146.397 | X3: 46146.412 | Y3: 01152741410 | Z3: 2994621296 | AA3: ENTRANTE | AB3: FULL | AC3: 2994621296-149044343-20260504093134.mp3 | AE3: NAC-CEL | AF3: NACIONAL | AG3: PAIS-CELULAR | AH3: 0 | AI3: 0 | AJ3: 0 | AK3: 0 | AL3: BL | AM3: 3 | AN3: 1264 | AO3: NotSet | AP3: 37 | AQ3: 198 | AR3: 2466160 | AT3: |0||SIP/SERVICIOS_SIP-00000eb2|1777897928.3771|16:Normal Clearing|16:PBX|6|SIP/GQ106-00000ec7|-1|NotSet|
A4: =+CONCATENATE(DAY(V4),"/",MONTH(V4),"/",YEAR(V4),"")*1 -> 46146 | B4: =+Z4*1 -> 3876349552 | C4: =+AA4 -> ENTRANTE | D4: =VLOOKUP(Q4,Code!E:F,2,0) -> Admisiones | E4: Conectadas | F4: =+AP4 -> 37 | G4: =+S4 -> 27 | H4: =+HOUR(V4) -> 19 | I4: =IFERROR(VLOOKUP(B4,MATRICULAS!A:B,2,0),0)*1 -> 0 | J4: 20260504 | K4: 149059248 | L4: SERVICIOS_SIP | M4: NEO1 | N4: 0 | O4: 0 | P4: CAMPAÑA | Q4: 150 | R4: 8864 - González, Maitena | S4: 27 | T4: ANSWER | U4: AGENT | V4: 46146.827 | W4: 46146.827 | X4: 46146.836 | Y4: 01152741410 | Z4: 3876349552 | AA4: ENTRANTE | AB4: FULL | AC4: 3876349552-149059248-20260504195033.mp3 | AE4: NAC-FIJO | AF4: SALTA | AG4: METAN | AH4: 0 | AI4: 0 | AJ4: 0 | AK4: 0 | AL4: BL | AM4: 3 | AN4: 810 | AO4: NotSet | AP4: 37 | AQ4: 116 | AR4: 1425078 | AT4: |0||SIP/SERVICIOS_SIP-00007e20|1777935066.32316|16:Normal Clearing|16:PBX|7|SIP/GQ114-00007e2f|-1|NotSet|
A5: =+CONCATENATE(DAY(V5),"/",MONTH(V5),"/",YEAR(V5),"")*1 -> 46146 | B5: =+Z5*1 -> 1157740540 | C5: =+AA5 -> ENTRANTE | D5: =VLOOKUP(Q5,Code!E:F,2,0) -> Admisiones | E5: Conectadas | F5: =+AP5 -> 37 | G5: =+S5 -> 27 | H5: =+HOUR(V5) -> 19 | I5: =IFERROR(VLOOKUP(B5,MATRICULAS!A:B,2,0),0)*1 -> 0 | J5: 20260504 | K5: 149058778 | L5: SERVICIOS_SIP | M5: NEO1 | N5: 0 | O5: 0 | P5: CAMPAÑA | Q5: 150 | R5: 8864 - González, Maitena | S5: 27 | T5: ANSWER | U5: AGENT | V5: 46146.814 | W5: 46146.814 | X5: 46146.818 | Y5: 01152741410 | Z5: 1157740540 | AA5: ENTRANTE | AB5: FULL | AC5: 1157740540-149058778-20260504193214.mp3 | AE5: NAC-CEL | AF5: NACIONAL | AG5: PAIS-CELULAR | AH5: 0 | AI5: 0 | AJ5: 0 | AK5: 0 | AL5: BL | AM5: 3 | AN5: 304 | AO5: NotSet | AP5: 37 | AQ5: 202 | AR5: 2487388 | AT5: |0||SIP/SERVICIOS_SIP-00007a93|1777933967.31406|16:Normal Clearing|16:PBX|16||-1|NotSet|
A6: =+CONCATENATE(DAY(V6),"/",MONTH(V6),"/",YEAR(V6),"")*1 -> 46146 | B6: =+Z6*1 -> 1151394081 | C6: =+AA6 -> ENTRANTE | D6: =VLOOKUP(Q6,Code!E:F,2,0) -> Admisiones | E6: Conectadas | F6: =+AP6 -> 37 | G6: =+S6 -> 27 | H6: =+HOUR(V6) -> 18 | I6: =IFERROR(VLOOKUP(B6,MATRICULAS!A:B,2,0),0)*1 -> 1 | J6: 20260504 | K6: 149056627 | L6: SERVICIOS_SIP | M6: NEO1 | N6: 0 | O6: 0 | P6: CAMPAÑA | Q6: 150 | R6: 8864 - González, Maitena | S6: 27 | T6: ANSWER | U6: AGENT | V6: 46146.756 | W6: 46146.756 | X6: 46146.758 | Y6: 01152741410 | Z6: 1151394081 | AA6: ENTRANTE | AB6: FULL | AC6: 1151394081-149056627-20260504180802.mp3 | AE6: NAC-CEL | AF6: NACIONAL | AG6: PAIS-CELULAR | AH6: 0 | AI6: 0 | AJ6: 0 | AK6: 0 | AL6: BL | AM6: 3 | AN6: 194 | AO6: NotSet | AP6: 37 | AQ6: 201 | AR6: 2487280 | AT6: |0||SIP/SERVICIOS_SIP-00006a92|1777928916.27306|16:Normal Clearing|17:Network|10||-1|NotSet|
A7: =+CONCATENATE(DAY(V7),"/",MONTH(V7),"/",YEAR(V7),"")*1 -> 46146 | B7: =+Z7*1 -> 3585611503 | C7: =+AA7 -> ENTRANTE | D7: =VLOOKUP(Q7,Code!E:F,2,0) -> Admisiones | E7: Conectadas | F7: =+AP7 -> 37 | G7: =+S7 -> 27 | H7: =+HOUR(V7) -> 18 | I7: =IFERROR(VLOOKUP(B7,MATRICULAS!A:B,2,0),0)*1 -> 0 | J7: 20260504 | K7: 149056539 | L7: SERVICIOS_SIP | M7: NEO1 | N7: 0 | O7: 0 | P7: CAMPAÑA | Q7: 150 | R7: 8814 - Nievas, Jimena | S7: 27 | T7: ANSWER | U7: AGENT | V7: 46146.753 | W7: 46146.753 | X7: 46146.755 | Y7: 01152741410 | Z7: 3585611503 | AA7: ENTRANTE | AB7: FULL | AC7: 3585611503-149056539-20260504180458.mp3 | AE7: NAC-CEL | AF7: NACIONAL | AG7: PAIS-CELULAR | AH7: 0 | AI7: 0 | AJ7: 0 | AK7: 0 | AL7: BL | AM7: 3 | AN7: 160 | AO7: NotSet | AP7: 37 | AQ7: 0 | AR7: 0 | AT7: |0||SIP/SERVICIOS_SIP-000069ec|1777928731.27140|16:Normal Clearing|17:Network|0||-1|NotSet|
A8: =+CONCATENATE(DAY(V8),"/",MONTH(V8),"/",YEAR(V8),"")*1 -> 46146 | B8: =+Z8*1 -> 1160047038 | C8: =+AA8 -> ENTRANTE | D8: =VLOOKUP(Q8,Code!E:F,2,0) -> Admisiones | E8: Conectadas | F8: =+AP8 -> 37 | G8: =+S8 -> 27 | H8: =+HOUR(V8) -> 17 | I8: =IFERROR(VLOOKUP(B8,MATRICULAS!A:B,2,0),0)*1 -> 0 | J8: 20260504 | K8: 149056266 | L8: SERVICIOS_SIP | M8: NEO1 | N8: 0 | O8: 0 | P8: CAMPAÑA | Q8: 150 | R8: 8872 - Pasetti, Gisela Lorena | S8: 27 | T8: ANSWER | U8: AGENT | V8: 46146.746 | W8: 46146.746 | X8: 46146.755 | Y8: 01152741410 | Z8: 1160047038 | AA8: ENTRANTE | AB8: FULL | AC8: 1160047038-149056266-20260504175352.mp3 | AE8: NAC-CEL | AF8: NACIONAL | AG8: PAIS-CELULAR | AH8: 0 | AI8: 0 | AJ8: 0 | AK8: 0 | AL8: BL | AM8: 3 | AN8: 797 | AO8: NotSet | AP8: 37 | AQ8: 202 | AR8: 2486227 | AT8: |0||SIP/SERVICIOS_SIP-000067e6|1777928065.26622|16:Normal Clearing|16:PBX|12|SIP/GQ105-000067f8|-1|NotSet|
A9: =+CONCATENATE(DAY(V9),"/",MONTH(V9),"/",YEAR(V9),"")*1 -> 46146 | B9: =+Z9*1 -> 1132713706 | C9: =+AA9 -> ENTRANTE | D9: =VLOOKUP(Q9,Code!E:F,2,0) -> Admisiones | E9: Conectadas | F9: =+AP9 -> 37 | G9: =+S9 -> 27 | H9: =+HOUR(V9) -> 16 | I9: =IFERROR(VLOOKUP(B9,MATRICULAS!A:B,2,0),0)*1 -> 1 | J9: 20260504 | K9: 149055190 | L9: SERVICIOS_SIP | M9: NEO1 | N9: 0 | O9: 0 | P9: CAMPAÑA | Q9: 150 | R9: 8814 - Nievas, Jimena | S9: 27 | T9: ANSWER | U9: AGENT | V9: 46146.708 | W9: 46146.708 | X9: 46146.713 | Y9: 01152741410 | Z9: 1132713706 | AA9: ENTRANTE | AB9: FULL | AC9: 1132713706-149055190-20260504165915.mp3 | AE9: NAC-CEL | AF9: NACIONAL | AG9: PAIS-CELULAR | AH9: 0 | AI9: 0 | AJ9: 0 | AK9: 0 | AL9: BL | AM9: 3 | AN9: 470 | AO9: NotSet | AP9: 37 | AQ9: 199 | AR9: 2483055 | AT9: |0||SIP/SERVICIOS_SIP-00005fc4|1777924789.24538|16:Normal Clearing|17:Network|18||-1|NotSet|
A10: =+CONCATENATE(DAY(V10),"/",MONTH(V10),"/",YEAR(V10),"")*1 -> 46146 | B10: =+Z10*1 -> 1140450044 | C10: =+AA10 -> ENTRANTE | D10: =VLOOKUP(Q10,Code!E:F,2,0) -> Admisiones | E10: Conectadas | F10: =+AP10 -> 37 | G10: =+S10 -> 27 | H10: =+HOUR(V10) -> 16 | I10: =IFERROR(VLOOKUP(B10,MATRICULAS!A:B,2,0),0)*1 -> 0 | J10: 20260504 | K10: 149055078 | L10: SERVICIOS_SIP | M10: NEO1 | N10: 0 | O10: 0 | P10: CAMPAÑA | Q10: 150 | R10: 8872 - Pasetti, Gisela Lorena | S10: 27 | T10: ANSWER | U10: AGENT | V10: 46146.706 | W10: 46146.706 | X10: 46146.714 | Y10: 01152741410 | Z10: 1140450044 | AA10: ENTRANTE | AB10: FULL | AC10: 1140450044-149055078-20260504165601.mp3 | AE10: NAC-CEL | AF10: NACIONAL | AG10: PAIS-CELULAR | AH10: 0 | AI10: 0 | AJ10: 0 | AK10: 0 | AL10: BL | AM10: 3 | AN10: 766 | AO10: NotSet | AP10: 37 | AQ10: 202 | AR10: 2487045 | AT10: |0||SIP/SERVICIOS_SIP-00005ef6|1777924595.24332|16:Normal Clearing|16:PBX|16||-1|NotSet|
A11: =+CONCATENATE(DAY(V11),"/",MONTH(V11),"/",YEAR(V11),"")*1 -> 46146 | B11: =+Z11*1 -> 2983618493 | C11: =+AA11 -> ENTRANTE | D11: =VLOOKUP(Q11,Code!E:F,2,0) -> Admisiones | E11: Conectadas | F11: =+AP11 -> 37 | G11: =+S11 -> 27 | H11: =+HOUR(V11) -> 16 | I11: =IFERROR(VLOOKUP(B11,MATRICULAS!A:B,2,0),0)*1 -> 0 | J11: 20260504 | K11: 149054197 | L11: SERVICIOS_SIP | M11: NEO1 | N11: 0 | O11: 0 | P11: CAMPAÑA | Q11: 150 | R11: 8864 - González, Maitena | S11: 27 | T11: ANSWER | U11: AGENT | V11: 46146.682 | W11: 46146.682 | X11: 46146.687 | Y11: 01152741410 | Z11: 2983618493 | AA11: ENTRANTE | AB11: FULL | AC11: 2983618493-149054197-20260504162232.mp3 | AE11: NAC-CEL | AF11: NACIONAL | AG11: PAIS-CELULAR | AH11: 0 | AI11: 0 | AJ11: 0 | AK11: 0 | AL11: BL | AM11: 3 | AN11: 421 | AO11: NotSet | AP11: 37 | AQ11: 1 | AR11: 2487183 | AT11: |0||SIP/SERVICIOS_SIP-00005851|1777922586.22628|16:Normal Clearing|16:PBX|17|SIP/GQ114-00005864|-1|NotSet|
A12: =+CONCATENATE(DAY(V12),"/",MONTH(V12),"/",YEAR(V12),"")*1 -> 46146 | B12: =+Z12*1 -> 2966784318 | C12: =+AA12 -> ENTRANTE | D12: =VLOOKUP(Q12,Code!E:F,2,0) -> Admisiones | E12: Conectadas | F12: =+AP12 -> 37 | G12: =+S12 -> 0 | H12: =+HOUR(V12) -> 16 | I12: =IFERROR(VLOOKUP(B12,MATRICULAS!A:B,2,0),0)*1 -> 0 | J12: 20260504 | K12: 149053813 | L12: SERVICIOS_SIP | M12: NEO1 | N12: 0 | O12: 0 | P12: CAMPAÑA | Q12: 150 | R12: 8984 - Cejas, Nahuel | S12: 0 | T12: ANSWER | U12: AGENT | V12: 46146.67 | W12: 46146.67 | X12: 46146.679 | Y12: 01152741410 | Z12: 2966784318 | AA12: ENTRANTE | AB12: FULL | AC12: 2966784318-149053813-20260504160430.mp3 | AE12: NAC-FIJO | AF12: SANTA CRUZ | AG12: RIO GALLEGOS | AH12: 0 | AI12: 0 | AJ12: 0 | AK12: 0 | AL12: BL | AM12: 3 | AN12: 768 | AO12: NotSet | AP12: 37 | AQ12: 174 | AR12: 2238299 | AT12: |0||SIP/SERVICIOS_SIP-0000553d|1777921504.21839|16:Normal Clearing|17:Network|18||-1|NotSet|
A13: =+CONCATENATE(DAY(V13),"/",MONTH(V13),"/",YEAR(V13),"")*1 -> 46146 | B13: =+Z13*1 -> 1136654608 | C13: =+AA13 -> ENTRANTE | D13: =VLOOKUP(Q13,Code!E:F,2,0) -> Admisiones | E13: Conectadas | F13: =+AP13 -> 37 | G13: =+S13 -> 27 | H13: =+HOUR(V13) -> 15 | I13: =IFERROR(VLOOKUP(B13,MATRICULAS!A:B,2,0),0)*1 -> 0 | J13: 20260504 | K13: 149052887 | L13: SERVICIOS_SIP | M13: NEO1 | N13: 0 | O13: 0 | P13: CAMPAÑA | Q13: 150 | R13: 8864 - González, Maitena | S13: 27 | T13: ANSWER | U13: AGENT | V13: 46146.63 | W13: 46146.63 | X13: 46146.635 | Y13: 01152741410 | Z13: 1136654608 | AA13: ENTRANTE | AB13: FULL | AC13: 1136654608-149052887-20260504150752.mp3 | AE13: NAC-CEL | AF13: NACIONAL | AG13: PAIS-CELULAR | AH13: 0 | AI13: 0 | AJ13: 0 | AK13: 0 | AL13: BL | AM13: 3 | AN13: 364 | AO13: NotSet | AP13: 37 | AQ13: 202 | AR13: 2486961 | AT13: |0||SIP/SERVICIOS_SIP-00004e24|1777918106.20019|16:Normal Clearing|16:PBX|2|SIP/GQ114-00004e2e|-1|NotSet|
... A22: =+CONCATENATE(DAY(V22),"/",MONTH(V22),"/",YEAR(V22),"")*1 -> 46146 | B22: =+Z22*1 -> 1166798721 | C22: =+AA22 -> ENTRANTE | D22: =VLOOKUP(Q22,Code!E:F,2,0) -> Admisiones | E22: Conectadas | F22: =+AP22 -> 37 | G22: =+S22 -> 26 | H22: =+HOUR(V22) -> 11 | I22: =IFERROR(VLOOKUP(B22,MATRICULAS!A:B,2,0),0)*1 -> 0 | J22: 20260504 | K22: 149047443 | L22: SERVICIOS_SIP | M22: NEO1 | N22: 0 | O22: 0 | P22: CAMPAÑA | Q22: 150 | R22: 8160 - QUEVEDO, JOAHANA | S22: 26 | T22: ANSWER | U22: AGENT | V22: 46146.491 | W22: 46146.491 | X22: 46146.496 | Y22: 01152741410 | Z22: 1166798721 | AA22: ENTRANTE | AB22: FULL | AC22: 1166798721-149047443-20260504114640.mp3 | AE22: NAC-CEL | AF22: NACIONAL | AG22: PAIS-CELULAR | AH22: 0 | AI22: 0 | AJ22: 0 | AK22: 0 | AL22: BL | AM22: 3 | AN22: 445 | AO22: NotSet | AP22: 37 | AQ22: 199 | AR22: 2476878 | AT22: |0||SIP/SERVICIOS_SIP-000026aa|1777906034.9910|16:Normal Clearing|17:Network|19||-1|NotSet|
A23: =+CONCATENATE(DAY(V23),"/",MONTH(V23),"/",YEAR(V23),"")*1 -> 46146 | B23: =+Z23*1 -> 1159432774 | C23: =+AA23 -> ENTRANTE | D23: =VLOOKUP(Q23,Code!E:F,2,0) -> Admisiones | E23: Conectadas | F23: =+AP23 -> 37 | G23: =+S23 -> 26 | H23: =+HOUR(V23) -> 11 | I23: =IFERROR(VLOOKUP(B23,MATRICULAS!A:B,2,0),0)*1 -> 0 | J23: 20260504 | K23: 149046617 | L23: SERVICIOS_SIP | M23: NEO1 | N23: 0 | O23: 0 | P23: CAMPAÑA | Q23: 150 | R23: 8861 - Caceres, Martina | S23: 26 | T23: ANSWER | U23: AGENT | V23: 46146.469 | W23: 46146.469 | X23: 46146.477 | Y23: 01152741410 | Z23: 1159432774 | AA23: ENTRANTE | AB23: FULL | AC23: 1159432774-149046617-20260504111502.mp3 | AE23: NAC-CEL | AF23: NACIONAL | AG23: PAIS-CELULAR | AH23: 0 | AI23: 0 | AJ23: 0 | AK23: 0 | AL23: BL | AM23: 3 | AN23: 746 | AO23: NotSet | AP23: 37 | AQ23: 1 | AR23: 2483262 | AS23: Apr 30 2026 1:12PM | AT23: |0||SIP/SERVICIOS_SIP-00002087|1777904136.8339|16:Normal Clearing|16:PBX|20|SIP/GQ106-00002096|-1|NotSet|
A24: =+CONCATENATE(DAY(V24),"/",MONTH(V24),"/",YEAR(V24),"")*1 -> 46146 | B24: =+Z24*1 -> 3884459927 | C24: =+AA24 -> ENTRANTE | D24: =VLOOKUP(Q24,Code!E:F,2,0) -> Admisiones | E24: Conectadas | F24: =+AP24 -> 37 | G24: =+S24 -> 26 | H24: =+HOUR(V24) -> 11 | I24: =IFERROR(VLOOKUP(B24,MATRICULAS!A:B,2,0),0)*1 -> 0 | J24: 20260504 | K24: 149046493 | L24: SERVICIOS_SIP | M24: NEO1 | N24: 0 | O24: 0 | P24: CAMPAÑA | Q24: 150 | R24: 8861 - Caceres, Martina | S24: 26 | T24: ANSWER | U24: AGENT | V24: 46146.462 | W24: 46146.462 | X24: 46146.469 | Y24: 01152741410 | Z24: 3884459927 | AA24: ENTRANTE | AB24: FULL | AC24: 3884459927-149046493-20260504110544.mp3 | AE24: NAC-FIJO | AF24: JUJUY | AG24: SAN PEDRO (PROV. JUJUY) | AH24: 0 | AI24: 0 | AJ24: 0 | AK24: 0 | AL24: BL | AM24: 3 | AN24: 558 | AO24: NotSet | AP24: 37 | AQ24: 1 | AR24: 2357572 | AS24: Feb 11 2026 10:06AM | AT24: |0||SIP/SERVICIOS_SIP-00001f83|1777903578.8079|16:Normal Clearing|16:PBX|20|SIP/GQ106-00001f87|-1|NotSet|
A25: =+CONCATENATE(DAY(V25),"/",MONTH(V25),"/",YEAR(V25),"")*1 -> 46146 | B25: =+Z25*1 -> 3517333437 | C25: =+AA25 -> ENTRANTE | D25: =VLOOKUP(Q25,Code!E:F,2,0) -> Admisiones | E25: Conectadas | F25: =+AP25 -> 37 | G25: =+S25 -> 26 | H25: =+HOUR(V25) -> 10 | I25: =IFERROR(VLOOKUP(B25,MATRICULAS!A:B,2,0),0)*1 -> 0 | J25: 20260504 | K25: 149046381 | L25: SERVICIOS_SIP | M25: NEO1 | N25: 0 | O25: 0 | P25: CAMPAÑA | Q25: 150 | R25: 8160 - QUEVEDO, JOAHANA | S25: 26 | T25: ANSWER | U25: AGENT | V25: 46146.458 | W25: 46146.458 | X25: 46146.464 | Y25: 01152741410 | Z25: 3517333437 | AA25: ENTRANTE | AB25: FULL | AC25: 3517333437-149046381-20260504105946.mp3 | AE25: NAC-FIJO | AF25: CORDOBA | AG25: CORDOBA | AH25: 0 | AI25: 0 | AJ25: 0 | AK25: 0 | AL25: BL | AM25: 3 | AN25: 483 | AO25: NotSet | AP25: 37 | AQ25: 201 | AR25: 2486231 | AT25: |0||SIP/SERVICIOS_SIP-00001e98|1777903220.7843|16:Normal Clearing|17:Network|2||-1|NotSet|
A26: =+CONCATENATE(DAY(V26),"/",MONTH(V26),"/",YEAR(V26),"")*1 -> 46146 | B26: =+Z26*1 -> 1159035439 | C26: =+AA26 -> ENTRANTE | D26: =VLOOKUP(Q26,Code!E:F,2,0) -> Admisiones | E26: Conectadas | F26: =+AP26 -> 37 | G26: =+S26 -> 5 | H26: =+HOUR(V26) -> 10 | I26: =IFERROR(VLOOKUP(B26,MATRICULAS!A:B,2,0),0)*1 -> 0 | J26: 20260504 | K26: 149046332 | L26: SERVICIOS_SIP | M26: NEO1 | N26: 0 | O26: 0 | P26: CAMPAÑA | Q26: 150 | R26: 8160 - QUEVEDO, JOAHANA | S26: 5 | T26: ANSWER | U26: AGENT | V26: 46146.456 | W26: 46146.456 | X26: 46146.457 | Y26: 01152741410 | Z26: 1159035439 | AA26: ENTRANTE | AB26: FULL | AC26: 1159035439-149046332-20260504105652.mp3 | AE26: NAC-CEL | AF26: NACIONAL | AG26: PAIS-CELULAR | AH26: 0 | AI26: 0 | AJ26: 0 | AK26: 0 | AL26: BL | AM26: 3 | AN26: 71 | AO26: NotSet | AP26: 37 | AQ26: 0 | AR26: 0 | AT26: |0||SIP/SERVICIOS_SIP-00001e2a|1777903046.7733|16:Normal Clearing|17:Network|21||-1|NotSet|
A27: =+CONCATENATE(DAY(V27),"/",MONTH(V27),"/",YEAR(V27),"")*1 -> 46146 | B27: =+Z27*1 -> 3482535547 | C27: =+AA27 -> ENTRANTE | D27: =VLOOKUP(Q27,Code!E:F,2,0) -> Admisiones | E27: Conectadas | F27: =+AP27 -> 37 | G27: =+S27 -> 26 | H27: =+HOUR(V27) -> 10 | I27: =IFERROR(VLOOKUP(B27,MATRICULAS!A:B,2,0),0)*1 -> 0 | J27: 20260504 | K27: 149046181 | L27: SERVICIOS_SIP | M27: NEO1 | N27: 0 | O27: 0 | P27: CAMPAÑA | Q27: 150 | R27: 8861 - Caceres, Martina | S27: 26 | T27: ANSWER | U27: AGENT | V27: 46146.453 | W27: 46146.453 | X27: 46146.459 | Y27: 01152741410 | Z27: 3482535547 | AA27: ENTRANTE | AB27: FULL | AC27: 3482535547-149046181-20260504105148.mp3 | AE27: NAC-CEL | AF27: NACIONAL | AG27: PAIS-CELULAR | AH27: 0 | AI27: 0 | AJ27: 0 | AK27: 0 | AL27: BL | AM27: 3 | AN27: 550 | AO27: NotSet | AP27: 37 | AQ27: 201 | AR27: 2484927 | AT27: |0||SIP/SERVICIOS_SIP-00001d0a|1777902742.7444|16:Normal Clearing|16:PBX|7|SIP/GQ106-00001d19|-1|NotSet|
A28: =+CONCATENATE(DAY(V28),"/",MONTH(V28),"/",YEAR(V28),"")*1 -> 46146 | B28: =+Z28*1 -> 1170583210 | C28: =+AA28 -> ENTRANTE | D28: =VLOOKUP(Q28,Code!E:F,2,0) -> Admisiones | E28: Conectadas | F28: =+AP28 -> 37 | G28: =+S28 -> 26 | H28: =+HOUR(V28) -> 10 | I28: =IFERROR(VLOOKUP(B28,MATRICULAS!A:B,2,0),0)*1 -> 0 | J28: 20260504 | K28: 149045897 | L28: SERVICIOS_SIP | M28: NEO1 | N28: 0 | O28: 0 | P28: CAMPAÑA | Q28: 150 | R28: 8160 - QUEVEDO, JOAHANA | S28: 26 | T28: ANSWER | U28: AGENT | V28: 46146.438 | W28: 46146.438 | X28: 46146.45 | Y28: 01152741410 | Z28: 1170583210 | AA28: ENTRANTE | AB28: FULL | AC28: 1170583210-149045897-20260504103020.mp3 | AE28: LOC-FIJO | AF28: LOCAL-FIJO | AG28: LOCAL-FIJO | AH28: 0 | AI28: 0 | AJ28: 0 | AK28: 0 | AL28: BL | AM28: 3 | AN28: 1064 | AO28: NotSet | AP28: 37 | AQ28: 201 | AR28: 2486615 | AT28: |0||SIP/SERVICIOS_SIP-00001aca|1777901454.6868|16:Normal Clearing|17:Network|6||-1|NotSet|
A29: =+CONCATENATE(DAY(V29),"/",MONTH(V29),"/",YEAR(V29),"")*1 -> 46146 | B29: =+Z29*1 -> 1132570770 | C29: =+AA29 -> ENTRANTE | D29: =VLOOKUP(Q29,Code!E:F,2,0) -> Admisiones | E29: Conectadas | F29: =+AP29 -> 37 | G29: =+S29 -> 5 | H29: =+HOUR(V29) -> 10 | I29: =IFERROR(VLOOKUP(B29,MATRICULAS!A:B,2,0),0)*1 -> 0 | J29: 20260504 | K29: 149045894 | L29: SERVICIOS_SIP | M29: NEO1 | N29: 0 | O29: 0 | P29: CAMPAÑA | Q29: 150 | R29: 8647 - Molina, Rocio | S29: 5 | T29: ANSWER | U29: AGENT | V29: 46146.438 | W29: 46146.438 | X29: 46146.441 | Y29: 01152741410 | Z29: 1132570770 | AA29: ENTRANTE | AB29: FULL | AC29: 1132570770-149045894-20260504103006.mp3 | AE29: NAC-CEL | AF29: NACIONAL | AG29: PAIS-CELULAR | AH29: 0 | AI29: 0 | AJ29: 0 | AK29: 0 | AL29: BL | AM29: 3 | AN29: 309 | AO29: NotSet | AP29: 37 | AQ29: 114 | AR29: 788021 | AT29: |0||SIP/SERVICIOS_SIP-00001ac4|1777901440.6862|16:Normal Clearing|16:PBX|13|SIP/Z8647-00001ad1|-1|NotSet|
A30: =+CONCATENATE(DAY(V30),"/",MONTH(V30),"/",YEAR(V30),"")*1 -> 46146 | B30: =+Z30*1 -> 1136289001 | C30: =+AA30 -> ENTRANTE | D30: =VLOOKUP(Q30,Code!E:F,2,0) -> Admisiones | E30: Conectadas | F30: =+AP30 -> 37 | G30: =+S30 -> 26 | H30: =+HOUR(V30) -> 9 | I30: =IFERROR(VLOOKUP(B30,MATRICULAS!A:B,2,0),0)*1 -> 0 | J30: 20260504 | K30: 149044898 | L30: SERVICIOS_SIP | M30: NEO1 | N30: 0 | O30: 0 | P30: CAMPAÑA | Q30: 150 | R30: 8861 - Caceres, Martina | S30: 26 | T30: ANSWER | U30: AGENT | V30: 46146.412 | W30: 46146.412 | X30: 46146.418 | Y30: 01152741410 | Z30: 1136289001 | AA30: ENTRANTE | AB30: FULL | AC30: 1136289001-149044898-20260504095352.mp3 | AE30: NAC-CEL | AF30: NACIONAL | AG30: PAIS-CELULAR | AH30: 0 | AI30: 0 | AJ30: 0 | AK30: 0 | AL30: BL | AM30: 3 | AN30: 474 | AO30: NotSet | AP30: 37 | AQ30: 1 | AR30: 2486560 | AT30: |0||SIP/SERVICIOS_SIP-0000137f|1777899266.5000|16:Normal Clearing|16:PBX|4||-1|NotSet|
A31: =+CONCATENATE(DAY(V31),"/",MONTH(V31),"/",YEAR(V31),"")*1 -> 46147 | B31: =+Z31*1 -> 1177141445 | C31: =+AA31 -> ENTRANTE | D31: =VLOOKUP(Q31,Code!E:F,2,0) -> Admisiones | E31: Conectadas | F31: =+AP31 -> 37 | G31: =+S31 -> 27 | H31: =+HOUR(V31) -> 20 | I31: =IFERROR(VLOOKUP(B31,MATRICULAS!A:B,2,0),0)*1 -> 0 | J31: 20260505 | K31: 149079802 | L31: SERVICIOS_SIP | M31: NEO1 | N31: 0 | O31: 0 | P31: CAMPAÑA | Q31: 150 | R31: 8864 - González, Maitena | S31: 27 | T31: ANSWER | U31: AGENT | V31: 46147.852 | W31: 46147.852 | X31: 46147.856 | Y31: 01152741410 | Z31: 1177141445 | AA31: ENTRANTE | AB31: FULL | AC31: 1177141445-149079802-20260505202612.mp3 | AE31: LOC-FIJO | AF31: LOCAL-FIJO | AG31: LOCAL-FIJO | AH31: 0 | AI31: 0 | AJ31: 0 | AK31: 0 | AL31: BL | AM31: 3 | AN31: 411 | AO31: NotSet | AP31: 37 | AQ31: 1 | AR31: 2488819 | AT31: |0||SIP/SERVICIOS_SIP-0000906d|1778023608.36995|16:Normal Clearing|17:Network|17||-1|NotSet|
A32: =+CONCATENATE(DAY(V32),"/",MONTH(V32),"/",YEAR(V32),"")*1 -> 46147 | B32: =+Z32*1 -> 1173661985 | C32: =+AA32 -> ENTRANTE | D32: =VLOOKUP(Q32,Code!E:F,2,0) -> Admisiones | E32: Conectadas | F32: =+AP32 -> 37 | G32: =+S32 -> 27 | H32: =+HOUR(V32) -> 20 | I32: =IFERROR(VLOOKUP(B32,MATRICULAS!A:B,2,0),0)*1 -> 0 | J32: 20260505 | K32: 149079539 | L32: SERVICIOS_SIP | M32: NEO1 | N32: 0 | O32: 0 | P32: CAMPAÑA | Q32: 150 | R32: 8872 - Pasetti, Gisela Lorena | S32: 27 | T32: ANSWER | U32: AGENT | V32: 46147.843 | W32: 46147.843 | X32: 46147.844 | Y32: 01152741410 | Z32: 1173661985 | AA32: ENTRANTE | AB32: FULL | AC32: 1173661985-149079539-20260505201344.mp3 | AE32: LOC-FIJO | AF32: LOCAL-FIJO | AG32: LOCAL-FIJO | AH32: 0 | AI32: 0 | AJ32: 0 | AK32: 0 | AL32: BL | AM32: 3 | AN32: 124 | AO32: NotSet | AP32: 37 | AQ32: 201 | AR32: 2488783 | AT32: |0||SIP/SERVICIOS_SIP-00008e24|1778022860.36410|16:Normal Clearing|17:Network|13||-1|NotSet|
A33: =+CONCATENATE(DAY(V33),"/",MONTH(V33),"/",YEAR(V33),"")*1 -> 46147 | B33: =+Z33*1 -> 3456586938 | C33: =+AA33 -> ENTRANTE | D33: =VLOOKUP(Q33,Code!E:F,2,0) -> Admisiones | E33: Conectadas | F33: =+AP33 -> 37 | G33: =+S33 -> 27 | H33: =+HOUR(V33) -> 18 | I33: =IFERROR(VLOOKUP(B33,MATRICULAS!A:B,2,0),0)*1 -> 0 | J33: 20260505 | K33: 149077294 | L33: SERVICIOS_SIP | M33: NEO1 | N33: 0 | O33: 0 | P33: CAMPAÑA | Q33: 150 | R33: 8864 - González, Maitena | S33: 27 | T33: ANSWER | U33: AGENT | V33: 46147.777 | W33: 46147.777 | X33: 46147.78 | Y33: 01152741410 | Z33: 3456586938 | AA33: ENTRANTE | AB33: FULL | AC33: 3456586938-149077294-20260505183855.mp3 | AE33: NAC-FIJO | AF33: ENTRE RIOS | AG33: CHAJARI | AH33: 0 | AI33: 0 | AJ33: 0 | AK33: 0 | AL33: BL | AM33: 3 | AN33: 262 | AO33: NotSet | AP33: 37 | AQ33: 202 | AR33: 2488678 | AT33: |0||SIP/SERVICIOS_SIP-00007be0|1778017171.31733|16:Normal Clearing|17:Network|10||-1|NotSet|
A34: =+CONCATENATE(DAY(V34),"/",MONTH(V34),"/",YEAR(V34),"")*1 -> 46147 | B34: =+Z34*1 -> 1126250956 | C34: =+AA34 -> ENTRANTE | D34: =VLOOKUP(Q34,Code!E:F,2,0) -> Admisiones | E34: Conectadas | F34: =+AP34 -> 37 | G34: =+S34 -> 27 | H34: =+HOUR(V34) -> 18 | I34: =IFERROR(VLOOKUP(B34,MATRICULAS!A:B,2,0),0)*1 -> 0 | J34: 20260505 | K34: 149076787 | L34: SERVICIOS_SIP | M34: NEO1 | N34: 0 | O34: 0 | P34: CAMPAÑA | Q34: 150 | R34: 8872 - Pasetti, Gisela Lorena | S34: 27 | T34: ANSWER | U34: AGENT | V34: 46147.763 | W34: 46147.763 | X34: 46147.765 | Y34: 01152741410 | Z34: 1126250956 | AA34: ENTRANTE | AB34: FULL | AC34: 1126250956-149076787-20260505181917.mp3 | AE34: LOC-FIJO | AF34: LOCAL-FIJO | AG34: LOCAL-FIJO | AH34: 0 | AI34: 0 | AJ34: 0 | AK34: 0 | AL34: BL | AM34: 3 | AN34: 145 | AO34: NotSet | AP34: 37 | AQ34: 199 | AR34: 2471734 | AT34: |0||SIP/SERVICIOS_SIP-00007824|1778015993.30777|16:Normal Clearing|16:PBX|7|SIP/Z8872-0000782f|-1|NotSet|
A35: =+CONCATENATE(DAY(V35),"/",MONTH(V35),"/",YEAR(V35),"")*1 -> 46147 | B35: =+Z35*1 -> 1151041745 | C35: =+AA35 -> ENTRANTE | D35: =VLOOKUP(Q35,Code!E:F,2,0) -> Admisiones | E35: Conectadas | F35: =+AP35 -> 37 | G35: =+S35 -> 27 | H35: =+HOUR(V35) -> 18 | I35: =IFERROR(VLOOKUP(B35,MATRICULAS!A:B,2,0),0)*1 -> 0 | J35: 20260505 | K35: 149076682 | L35: SERVICIOS_SIP | M35: NEO1 | N35: 0 | O35: 0 | P35: CAMPAÑA | Q35: 150 | R35: 8864 - González, Maitena | S35: 27 | T35: ANSWER | U35: AGENT | V35: 46147.76 | W35: 46147.76 | X35: 46147.767 | Y35: 01152741410 | Z35: 1151041745 | AA35: ENTRANTE | AB35: FULL | AC35: 1151041745-149076682-20260505181408.mp3 | AE35: NAC-CEL | AF35: NACIONAL | AG35: PAIS-CELULAR | AH35: 0 | AI35: 0 | AJ35: 0 | AK35: 0 | AL35: BL | AM35: 3 | AN35: 595 | AO35: NotSet | AP35: 37 | AQ35: 1 | AR35: 2488660 | AT35: |0||SIP/SERVICIOS_SIP-00007755|1778015684.30570|16:Normal Clearing|16:PBX|6|SIP/GQ111-0000775e|-1|NotSet|
A36: =+CONCATENATE(DAY(V36),"/",MONTH(V36),"/",YEAR(V36),"")*1 -> 46147 | B36: =+Z36*1 -> 2477343294 | C36: =+AA36 -> ENTRANTE | D36: =VLOOKUP(Q36,Code!E:F,2,0) -> Admisiones | E36: Conectadas | F36: =+AP36 -> 37 | G36: =+S36 -> 27 | H36: =+HOUR(V36) -> 18 | I36: =IFERROR(VLOOKUP(B36,MATRICULAS!A:B,2,0),0)*1 -> 0 | J36: 20260505 | K36: 149076430 | L36: SERVICIOS_SIP | M36: NEO1 | N36: 0 | O36: 0 | P36: CAMPAÑA | Q36: 150 | R36: 8864 - González, Maitena | S36: 27 | T36: ANSWER | U36: AGENT | V36: 46147.752 | W36: 46147.752 | X36: 46147.753 | Y36: 01152741410 | Z36: 2477343294 | AA36: ENTRANTE | AB36: FULL | AC36: 2477343294-149076430-20260505180324.mp3 | AE36: NAC-CEL | AF36: NACIONAL | AG36: PAIS-CELULAR | AH36: 0 | AI36: 0 | AJ36: 0 | AK36: 0 | AL36: BL | AM36: 3 | AN36: 30 | AO36: NotSet | AP36: 37 | AQ36: 1 | AR36: 1186133 | AS36: Oct 25 2023 12:42PM | AT36: |0||SIP/SERVICIOS_SIP-0000757f|1778015040.30099|16:Normal Clearing|17:Network|0||-1|NotSet|
A37: =+CONCATENATE(DAY(V37),"/",MONTH(V37),"/",YEAR(V37),"")*1 -> 46147 | B37: =+Z37*1 -> 2645892969 | C37: =+AA37 -> ENTRANTE | D37: =VLOOKUP(Q37,Code!E:F,2,0) -> Admisiones | E37: Conectadas | F37: =+AP37 -> 37 | G37: =+S37 -> 27 | H37: =+HOUR(V37) -> 17 | I37: =IFERROR(VLOOKUP(B37,MATRICULAS!A:B,2,0),0)*1 -> 1 | J37: 20260505 | K37: 149075902 | L37: SERVICIOS_SIP | M37: NEO1 | N37: 0 | O37: 0 | P37: CAMPAÑA | Q37: 150 | R37: 8864 - González, Maitena | S37: 27 | T37: ANSWER | U37: AGENT | V37: 46147.734 | W37: 46147.734 | X37: 46147.739 | Y37: 01152741410 | Z37: 2645892969 | AA37: ENTRANTE | AB37: FULL | AC37: 2645892969-149075902-20260505173711.mp3 | AE37: NAC-FIJO | AF37: SAN JUAN | AG37: SAN JUAN | AH37: 0 | AI37: 0 | AJ37: 0 | AK37: 0 | AL37: BL | AM37: 3 | AN37: 422 | AO37: NotSet | AP37: 37 | AQ37: 157 | AR37: 1661380 | AT37: |0||SIP/SERVICIOS_SIP-0000718c|1778013467.29088|16:Normal Clearing|16:PBX|11|SIP/GQ111-00007194|-1|NotSet|
A38: =+CONCATENATE(DAY(V38),"/",MONTH(V38),"/",YEAR(V38),"")*1 -> 46147 | B38: =+Z38*1 -> 1150012996 | C38: =+AA38 -> ENTRANTE | D38: =VLOOKUP(Q38,Code!E:F,2,0) -> Admisiones | E38: Conectadas | F38: =+AP38 -> 37 | G38: =+S38 -> 27 | H38: =+HOUR(V38) -> 17 | I38: =IFERROR(VLOOKUP(B38,MATRICULAS!A:B,2,0),0)*1 -> 0 | J38: 20260505 | K38: 149075644 | L38: SERVICIOS_SIP | M38: NEO1 | N38: 0 | O38: 0 | P38: CAMPAÑA | Q38: 150 | R38: 8864 - González, Maitena | S38: 27 | T38: ANSWER | U38: AGENT | V38: 46147.724 | W38: 46147.724 | X38: 46147.725 | Y38: 01152741410 | Z38: 1150012996 | AA38: ENTRANTE | AB38: FULL | AC38: 1150012996-149075644-20260505172230.mp3 | AE38: NAC-CEL | AF38: NACIONAL | AG38: PAIS-CELULAR | AH38: 0 | AI38: 0 | AJ38: 0 | AK38: 0 | AL38: BL | AM38: 3 | AN38: 85 | AO38: NotSet | AP38: 37 | AQ38: 202 | AR38: 2488583 | AT38: |0||SIP/SERVICIOS_SIP-00006f57|1778012586.28523|16:Normal Clearing|17:Network|3||-1|NotSet|
A39: =+CONCATENATE(DAY(V39),"/",MONTH(V39),"/",YEAR(V39),"")*1 -> 46147 | B39: =+Z39*1 -> 2314536428 | C39: =+AA39 -> ENTRANTE | D39: =VLOOKUP(Q39,Code!E:F,2,0) -> Admisiones | E39: Conectadas | F39: =+AP39 -> 37 | G39: =+S39 -> 27 | H39: =+HOUR(V39) -> 16 | I39: =IFERROR(VLOOKUP(B39,MATRICULAS!A:B,2,0),0)*1 -> 0 | J39: 20260505 | K39: 149075039 | L39: SERVICIOS_SIP | M39: NEO1 | N39: 0 | O39: 0 | P39: CAMPAÑA | Q39: 150 | R39: 8872 - Pasetti, Gisela Lorena | S39: 27 | T39: ANSWER | U39: AGENT | V39: 46147.705 | W39: 46147.705 | X39: 46147.71 | Y39: 01152741410 | Z39: 2314536428 | AA39: ENTRANTE | AB39: FULL | AC39: 2314536428-149075039-20260505165512.mp3 | AE39: NAC-CEL | AF39: NACIONAL | AG39: PAIS-CELULAR | AH39: 0 | AI39: 0 | AJ39: 0 | AK39: 0 | AL39: BL | AM39: 3 | AN39: 451 | AO39: NotSet | AP39: 37 | AQ39: 201 | AR39: 2487559 | AT39: |0||SIP/SERVICIOS_SIP-00006a79|1778010948.27277|16:Normal Clearing|17:Network|9||-1|NotSet|
A40: =+CONCATENATE(DAY(V40),"/",MONTH(V40),"/",YEAR(V40),"")*1 -> 46147 | B40: =+Z40*1 -> 1168126088 | C40: =+AA40 -> ENTRANTE | D40: =VLOOKUP(Q40,Code!E:F,2,0) -> Admisiones | E40: Conectadas | F40: =+AP40 -> 37 | G40: =+S40 -> 27 | H40: =+HOUR(V40) -> 16 | I40: =IFERROR(VLOOKUP(B40,MATRICULAS!A:B,2,0),0)*1 -> 0 | J40: 20260505 | K40: 149074952 | L40: SERVICIOS_SIP | M40: NEO1 | N40: 0 | O40: 0 | P40: CAMPAÑA | Q40: 150 | R40: 8864 - González, Maitena | S40: 27 | T40: ANSWER | U40: AGENT | V40: 46147.704 | W40: 46147.704 | X40: 46147.706 | Y40: 01152741410 | Z40: 1168126088 | AA40: ENTRANTE | AB40: FULL | AC40: 1168126088-149074952-20260505165304.mp3 | AE40: NAC-CEL | AF40: NACIONAL | AG40: PAIS-CELULAR | AH40: 0 | AI40: 0 | AJ40: 0 | AK40: 0 | AL40: BL | AM40: 3 | AN40: 212 | AO40: NotSet | AP40: 37 | AQ40: 1 | AR40: 2488559 | AT40: |0||SIP/SERVICIOS_SIP-000069e3|1778010820.27127|16:Normal Clearing|17:Network|17||-1|NotSet|
A41: =+CONCATENATE(DAY(V41),"/",MONTH(V41),"/",YEAR(V41),"")*1 -> 46147 | B41: =+Z41*1 -> 1122987042 | C41: =+AA41 -> ENTRANTE | D41: =VLOOKUP(Q41,Code!E:F,2,0) -> Admisiones | E41: Conectadas | F41: =+AP41 -> 37 | G41: =+S41 -> 27 | H41: =+HOUR(V41) -> 16 | I41: =IFERROR(VLOOKUP(B41,MATRICULAS!A:B,2,0),0)*1 -> 0 | J41: 20260505 | K41: 149073607 | L41: SERVICIOS_SIP | M41: NEO1 | N41: 0 | O41: 0 | P41: CAMPAÑA | Q41: 150 | R41: 8872 - Pasetti, Gisela Lorena | S41: 27 | T41: ANSWER | U41: AGENT | V41: 46147.673 | W41: 46147.673 | X41: 46147.678 | Y41: 01152741410 | Z41: 1122987042 | AA41: ENTRANTE | AB41: FULL | AC41: 1122987042-149073607-20260505160928.mp3 | AE41: LOC-FIJO | AF41: LOCAL-FIJO | AG41: LOCAL-FIJO | AH41: 0 | AI41: 0 | AJ41: 0 | AK41: 0 | AL41: BL | AM41: 3 | AN41: 400 | AO41: NotSet | AP41: 37 | AQ41: 201 | AR41: 2488496 | AT41: |0||SIP/SERVICIOS_SIP-000060bc|1778008204.24784|16:Normal Clearing|17:Network|0||-1|NotSet|
A42: =+CONCATENATE(DAY(V42),"/",MONTH(V42),"/",YEAR(V42),"")*1 -> 46147 | B42: =+Z42*1 -> 1160472080 | C42: =+AA42 -> ENTRANTE | D42: =VLOOKUP(Q42,Code!E:F,2,0) -> Admisiones | E42: Conectadas | F42: =+AP42 -> 37 | G42: =+S42 -> 27 | H42: =+HOUR(V42) -> 15 | I42: =IFERROR(VLOOKUP(B42,MATRICULAS!A:B,2,0),0)*1 -> 0 | J42: 20260505 | K42: 149073269 | L42: SERVICIOS_SIP | M42: NEO1 | N42: 0 | O42: 0 | P42: CAMPAÑA | Q42: 150 | R42: 8814 - Nievas, Jimena | S42: 27 | T42: ANSWER | U42: AGENT | V42: 46147.666 | W42: 46147.666 | X42: 46147.673 | Y42: 01152741410 | Z42: 1160472080 | AA42: ENTRANTE | AB42: FULL | AC42: 1160472080-149073269-20260505155824.mp3 | AE42: NAC-CEL | AF42: NACIONAL | AG42: PAIS-CELULAR | AH42: 0 | AI42: 0 | AJ42: 0 | AK42: 0 | AL42: BL | AM42: 3 | AN42: 630 | AO42: NotSet | AP42: 37 | AQ42: 0 | AR42: 0 | AT42: |0||SIP/SERVICIOS_SIP-00005e5a|1778007540.24174|16:Normal Clearing|17:Network|7||-1|NotSet|
A43: =+CONCATENATE(DAY(V43),"/",MONTH(V43),"/",YEAR(V43),"")*1 -> 46147 | B43: =+Z43*1 -> 1127972034 | C43: =+AA43 -> ENTRANTE | D43: =VLOOKUP(Q43,Code!E:F,2,0) -> Admisiones | E43: Conectadas | F43: =+AP43 -> 37 | G43: =+S43 -> 27 | H43: =+HOUR(V43) -> 15 | I43: =IFERROR(VLOOKUP(B43,MATRICULAS!A:B,2,0),0)*1 -> 0 | J43: 20260505 | K43: 149072975 | L43: SERVICIOS_SIP | M43: NEO1 | N43: 0 | O43: 0 | P43: CAMPAÑA | Q43: 150 | R43: 8872 - Pasetti, Gisela Lorena | S43: 27 | T43: ANSWER | U43: AGENT | V43: 46147.659 | W43: 46147.659 | X43: 46147.666 | Y43: 01152741410 | Z43: 1127972034 | AA43: ENTRANTE | AB43: FULL | AC43: 1127972034-149072975-20260505154832.mp3 | AE43: LOC-FIJO | AF43: LOCAL-FIJO | AG43: LOCAL-FIJO | AH43: 0 | AI43: 0 | AJ43: 0 | AK43: 0 | AL43: BL | AM43: 3 | AN43: 604 | AO43: NotSet | AP43: 37 | AQ43: 1 | AR43: 2488486 | AT43: |0||SIP/SERVICIOS_SIP-00005c55|1778006948.23657|16:Normal Clearing|17:Network|4||-1|NotSet|
A44: =+CONCATENATE(DAY(V44),"/",MONTH(V44),"/",YEAR(V44),"")*1 -> 46147 | B44: =+Z44*1 -> 1159480846 | C44: =+AA44 -> ENTRANTE | D44: =VLOOKUP(Q44,Code!E:F,2,0) -> Admisiones | E44: Conectadas | F44: =+AP44 -> 37 | G44: =+S44 -> 27 | H44: =+HOUR(V44) -> 15 | I44: =IFERROR(VLOOKUP(B44,MATRICULAS!A:B,2,0),0)*1 -> 0 | J44: 20260505 | K44: 149072618 | L44: SERVICIOS_SIP | M44: NEO1 | N44: 0 | O44: 0 | P44: CAMPAÑA | Q44: 150 | R44: 8872 - Pasetti, Gisela Lorena | S44: 27 | T44: ANSWER | U44: AGENT | V44: 46147.651 | W44: 46147.651 | X44: 46147.654 | Y44: 01152741410 | Z44: 1159480846 | AA44: ENTRANTE | AB44: FULL | AC44: 1159480846-149072618-20260505153658.mp3 | AE44: NAC-CEL | AF44: NACIONAL | AG44: PAIS-CELULAR | AH44: 0 | AI44: 0 | AJ44: 0 | AK44: 0 | AL44: BL | AM44: 3 | AN44: 310 | AO44: NotSet | AP44: 37 | AQ44: 0 | AR44: 0 | AT44: |0||SIP/SERVICIOS_SIP-000059d8|1778006254.23020|16:Normal Clearing|17:Network|9||-1|NotSet|
A45: =+CONCATENATE(DAY(V45),"/",MONTH(V45),"/",YEAR(V45),"")*1 -> 46147 | B45: =+Z45*1 -> 1162311873 | C45: =+AA45 -> ENTRANTE | D45: =VLOOKUP(Q45,Code!E:F,2,0) -> Admisiones | E45: Conectadas | F45: =+AP45 -> 37 | G45: =+S45 -> 26 | H45: =+HOUR(V45) -> 14 | I45: =IFERROR(VLOOKUP(B45,MATRICULAS!A:B,2,0),0)*1 -> 1 | J45: 20260505 | K45: 149071293 | L45: SERVICIOS_SIP | M45: NEO1 | N45: 0 | O45: 0 | P45: CAMPAÑA | Q45: 150 | R45: 8927 - Lizarrondo, Candela | S45: 26 | T45: ANSWER | U45: AGENT | V45: 46147.613 | W45: 46147.613 | X45: 46147.616 | Y45: 01152741410 | Z45: 1162311873 | AA45: ENTRANTE | AB45: FULL | AC45: 1162311873-149071293-20260505144212.mp3 | AE45: NAC-CEL | AF45: NACIONAL | AG45: PAIS-CELULAR | AH45: 0 | AI45: 0 | AJ45: 0 | AK45: 0 | AL45: BL | AM45: 3 | AN45: 266 | AO45: NotSet | AP45: 37 | AQ45: 73 | AR45: 1922092 | AS45: Apr 22 2025 10:43AM | AT45: |0||SIP/SERVICIOS_SIP-0000501f|1778002968.20529|16:Normal Clearing|17:Network|23||-1|NotSet|
A46: =+CONCATENATE(DAY(V46),"/",MONTH(V46),"/",YEAR(V46),"")*1 -> 46147 | B46: =+Z46*1 -> 1130025940 | C46: =+AA46 -> ENTRANTE | D46: =VLOOKUP(Q46,Code!E:F,2,0) -> Admisiones | E46: Conectadas | F46: =+AP46 -> 37 | G46: =+S46 -> 26 | H46: =+HOUR(V46) -> 14 | I46: =IFERROR(VLOOKUP(B46,MATRICULAS!A:B,2,0),0)*1 -> 0 | J46: 20260505 | K46: 149070653 | L46: SERVICIOS_SIP | M46: NEO1 | N46: 0 | O46: 0 | P46: CAMPAÑA | Q46: 150 | R46: 8861 - Caceres, Martina | S46: 26 | T46: ANSWER | U46: AGENT | V46: 46147.596 | W46: 46147.596 | X46: 46147.602 | Y46: 01152741410 | Z46: 1130025940 | AA46: ENTRANTE | AB46: FULL | AC46: 1130025940-149070653-20260505141856.mp3 | AE46: NAC-CEL | AF46: NACIONAL | AG46: PAIS-CELULAR | AH46: 0 | AI46: 0 | AJ46: 0 | AK46: 0 | AL46: BL | AM46: 3 | AN46: 461 | AO46: NotSet | AP46: 37 | AQ46: 202 | AR46: 2486475 | AT46: |0||SIP/SERVICIOS_SIP-00004b80|1778001572.19342|16:Normal Clearing|16:PBX|15|SIP/GQ106-00004b94|-1|NotSet|
A47: =+CONCATENATE(DAY(V47),"/",MONTH(V47),"/",YEAR(V47),"")*1 -> 46147 | B47: =+Z47*1 -> 1161212996 | C47: =+AA47 -> ENTRANTE | D47: =VLOOKUP(Q47,Code!E:F,2,0) -> Admisiones | E47: Conectadas | F47: =+AP47 -> 37 | G47: =+S47 -> 26 | H47: =+HOUR(V47) -> 13 | I47: =IFERROR(VLOOKUP(B47,MATRICULAS!A:B,2,0),0)*1 -> 0 | J47: 20260505 | K47: 149068973 | L47: SERVICIOS_SIP | M47: NEO1 | N47: 0 | O47: 0 | P47: CAMPAÑA | Q47: 150 | R47: 8861 - Caceres, Martina | S47: 26 | T47: ANSWER | U47: AGENT | V47: 46147.551 | W47: 46147.551 | X47: 46147.565 | Y47: 01152741410 | Z47: 1161212996 | AA47: ENTRANTE | AB47: FULL | AC47: 1161212996-149068973-20260505131342.mp3 | AE47: NAC-CEL | AF47: NACIONAL | AG47: PAIS-CELULAR | AH47: 0 | AI47: 0 | AJ47: 0 | AK47: 0 | AL47: BL | AM47: 3 | AN47: 1179 | AO47: NotSet | AP47: 37 | AQ47: 1 | AR47: 2129549 | AS47: Sep 8 2025 11:18AM | AT47: |0||SIP/SERVICIOS_SIP-00003f55|1777997658.16227|16:Normal Clearing|16:PBX|6|SIP/GQ106-00003f6c|-1|NotSet|
A48: =+CONCATENATE(DAY(V48),"/",MONTH(V48),"/",YEAR(V48),"")*1 -> 46147 | B48: =+Z48*1 -> 1144923455 | C48: =+AA48 -> ENTRANTE | D48: =VLOOKUP(Q48,Code!E:F,2,0) -> Admisiones | E48: Conectadas | F48: =+AP48 -> 37 | G48: =+S48 -> 26 | H48: =+HOUR(V48) -> 12 | I48: =IFERROR(VLOOKUP(B48,MATRICULAS!A:B,2,0),0)*1 -> 0 | J48: 20260505 | K48: 149068041 | L48: SERVICIOS_SIP | M48: NEO1 | N48: 0 | O48: 0 | P48: CAMPAÑA | Q48: 150 | R48: 8861 - Caceres, Martina | S48: 26 | T48: ANSWER | U48: AGENT | V48: 46147.528 | W48: 46147.528 | X48: 46147.533 | Y48: 01152741410 | Z48: 1144923455 | AA48: ENTRANTE | AB48: FULL | AC48: 1144923455-149068041-20260505124049.mp3 | AE48: NAC-CEL | AF48: NACIONAL | AG48: PAIS-CELULAR | AH48: 0 | AI48: 0 | AJ48: 0 | AK48: 0 | AL48: BL | AM48: 3 | AN48: 365 | AO48: NotSet | AP48: 37 | AQ48: 201 | AR48: 2488058 | AT48: |0||SIP/SERVICIOS_SIP-0000390e|1777995685.14620|16:Normal Clearing|17:Network|11||-1|NotSet|
...

Sheet Tabla dinamica
B1: 0800-222-3340
B7: Lunes | C7: =TEXT(C9,"dddd") -> martes | D7: =TEXT(D9,"dddd") -> miércoles | E7: =TEXT(E9,"dddd") -> jueves | F7: =TEXT(F9,"dddd") -> viernes | G7: =TEXT(G9,"dddd") -> lunes | H7: =TEXT(H9,"dddd") -> martes | I7: =TEXT(I9,"dddd") -> miércoles | J7: =TEXT(J9,"dddd") -> jueves | ... W7: =TEXT(W9,"dddd") -> sábado
A8: Fecha. | B8: Etiquetas de columna
A9: Horario | B9: 46146 | C9: 46147 | D9: 46148 | E9: 46149 | F9: 46150 | G9: 46153 | H9: 46154 | I9: 46155 | J9: 46156 | K9: 46157 | L9: 46160 | M9: 46161 | N9: 46162 | O9: 46163 | P9: 46164 | Q9: 46168 | R9: 46169 | S9: 46170 | T9: 46171 | U9: Total general
A10: 9 | B10: 3 | D10: 2 | E10: 3 | F10: 1 | G10: 2 | H10: 2 | J10: 1 | L10: 2 | N10: 2 | O10: 1 | P10: 6 | Q10: 2 | R10: 2 | S10: 3 | T10: 1 | U10: 33
A11: 10 | B11: 5 | C11: 2 | D11: 3 | E11: 4 | F11: 3 | G11: 5 | I11: 3 | J11: 3 | K11: 2 | L11: 4 | N11: 1 | O11: 5 | P11: 2 | Q11: 4 | R11: 3 | S11: 5 | U11: 54
A12: 11 | B12: 4 | C12: 3 | D12: 1 | E12: 2 | F12: 1 | G12: 1 | H12: 4 | I12: 2 | K12: 3 | L12: 5 | M12: 2 | N12: 2 | O12: 3 | P12: 3 | Q12: 6 | R12: 3 | S12: 1 | T12: 1 | U12: 47
A13: 12 | B13: 2 | C13: 1 | D13: 5 | E13: 2 | F13: 3 | G13: 2 | H13: 4 | K13: 3 | L13: 6 | M13: 3 | P13: 1 | Q13: 2 | S13: 3 | T13: 1 | U13: 38
A14: 13 | B14: 1 | C14: 1 | D14: 2 | F14: 4 | G14: 2 | H14: 2 | J14: 3 | K14: 2 | L14: 2 | M14: 3 | N14: 5 | O14: 1 | P14: 2 | Q14: 2 | R14: 2 | S14: 3 | T14: 2 | U14: 39
A15: 14 | B15: 4 | C15: 2 | D15: 2 | E15: 1 | F15: 2 | G15: 2 | H15: 1 | J15: 2 | L15: 1 | M15: 2 | O15: 3 | P15: 2 | Q15: 2 | R15: 1 | S15: 2 | U15: 29
A16: 15 | B16: 1 | C16: 3 | E16: 2 | F16: 2 | G16: 2 | H16: 4 | I16: 2 | K16: 1 | L16: 2 | M16: 4 | N16: 1 | P16: 1 | Q16: 1 | R16: 2 | S16: 1 | T16: 1 | U16: 30
A17: 16 | B17: 4 | C17: 3 | D17: 5 | F17: 1 | G17: 4 | H17: 2 | I17: 1 | J17: 3 | K17: 3 | L17: 1 | M17: 2 | N17: 1 | O17: 1 | Q17: 1 | R17: 2 | S17: 2 | T17: 3 | U17: 39
A18: 17 | B18: 1 | C18: 2 | D18: 2 | E18: 1 | F18: 1 | H18: 1 | I18: 2 | K18: 3 | L18: 3 | M18: 4 | N18: 1 | O18: 3 | P18: 1 | Q18: 4 | R18: 1 | S18: 3 | T18: 3 | U18: 36
A19: 18 | B19: 2 | C19: 4 | D19: 3 | E19: 1 | H19: 1 | I19: 3 | M19: 3 | N19: 1 | O19: 4 | Q19: 1 | R19: 1 | U19: 24
A20: 19 | B20: 2 | D20: 1 | G20: 1 | H20: 3 | J20: 1 | K20: 4 | L20: 2 | M20: 1 | N20: 2 | O20: 1 | T20: 4 | U20: 22
A21: 20 | C21: 2 | D21: 4 | E21: 3 | G21: 3 | H21: 1 | I21: 1 | J21: 1 | L21: 1 | N21: 2 | O21: 1 | P21: 1 | Q21: 1 | R21: 1 | T21: 1 | U21: 23
A22: Total general | B22: 29 | C22: 23 | D22: 30 | E22: 19 | F22: 18 | G22: 24 | H22: 25 | I22: 14 | J22: 14 | K22: 21 | L22: 29 | M22: 24 | N22: 18 | O22: 23 | P22: 19 | Q22: 26 | R22: 18 | S22: 23 | T22: 17 | U22: 414
A23: Horas | B23: Llamadas
A24: 9 | B24: =+GETPIVOTDATA("fecha real",$A$8,"hora de contacta",9) -> 33
A25: 10 | B25: =+GETPIVOTDATA("fecha real",$A$8,"hora de contacta",10) -> 54
A26: 11 | B26: =+GETPIVOTDATA("fecha real",$A$8,"hora de contacta",11) -> 47
A27: 12 | B27: =+GETPIVOTDATA("fecha real",$A$8,"hora de contacta",12) -> 38
A28: 13 | B28: =+GETPIVOTDATA("fecha real",$A$8,"hora de contacta",13) -> 39
A29: 14 | B29: =+GETPIVOTDATA("fecha real",$A$8,"hora de contacta",14) -> 29
A30: 15 | B30: =+GETPIVOTDATA("fecha real",$A$8,"hora de contacta",15) -> 30
A31: 16 | B31: =+GETPIVOTDATA("fecha real",$A$8,"hora de contacta",16) -> 39
A32: 17 | B32: =+GETPIVOTDATA("fecha real",$A$8,"hora de contacta",17) -> 36
A33: 18 | B33: =+GETPIVOTDATA("fecha real",$A$8,"hora de contacta",18) -> 24
A34: 19 | B34: =+GETPIVOTDATA("fecha real",$A$8,"hora de contacta",19) -> 22
A35: 20 | B35: =+GETPIVOTDATA("fecha real",$A$8,"hora de contacta",20) -> 23
A36: Total general | B36: =+SUM(B24:B34) -> 391

Sheet MATRICULAS
A1: Telefono | B1: ASA
A2: 43763632 | B2: 1
A3: 2235907995 | B3: 1
A4: 2964696700 | B4: 1
A5: 2995954223 | B5: 1
A6: 3704773824 | B6: 1
A7: 3624206505 | B7: 1
A8: 2614180707 | B8: 1
A9: 1163767740 | B9: 1
A10: 2994515454 | B10: 1
A11: 2645284787 | B11: 1
A12: 3735442634 | B12: 1
A13: 3875185276 | B13: 1
... A617: 2974701238 | B617: 1
B618: 1
B619: 1
B620: 1
B621: 1
B622: 1
B623: 1
B624: 1
B625: 1
B626: 1
B627: 1
B628: 1
B629: 1
... B8180: 1

Sheet Hoja3
A1: Linea | B1: AS
A2: 2974710793 | B2: 1
A3: 1151125419 | B3: 1
A4: 1136805781 | B4: 1
A5: 1133865407 | B5: 1
A6: 3758458760 | B6: 1
A7: 1168496167 | B7: 1
A8: 1150581075 | B8: 1
A9: 1158960601 | B9: 1
A10: 3434285285 | B10: 1
A11: 1154105594 | B11: 1
A12: 3456028486 | B12: 1
A13: 2966713589 | B13: 1
... A94: 2284679325 | B94: 1

Sheet Entrantes admisiones
A1: fecha real | B1: (Todas)
A3: Etiquetas de fila | B3: Cuenta de Conexión | C3: %
A4: Conectadas | B4: 414 | C4: 1
A5: 9 | B5: 33 | C5: 0.079710145
A6: 10 | B6: 54 | C6: 0.13043478
A7: 11 | B7: 47 | C7: 0.11352657
A8: 12 | B8: 38 | C8: 0.09178744
A9: 13 | B9: 39 | C9: 0.094202899
A10: 14 | B10: 29 | C10: 0.070048309
A11: 15 | B11: 30 | C11: 0.072463768
A12: 16 | B12: 39 | C12: 0.094202899
A13: 17 | B13: 36 | C13: 0.086956522
A14: 18 | B14: 24 | C14: 0.057971014
A15: 19 | B15: 22 | C15: 0.053140097
A16: 20 | B16: 23 | C16: 0.055555556
A17: Total general | B17: 414 | C17: 1
I19: Atendidas | J19: Perdidas
I20: =+GETPIVOTDATA("Cuenta de Conexión",$A$3,"Conexión","Conectadas") -> 414 | J20: =+GETPIVOTDATA("Cuenta de Conexión",$A$3,"Conexión","Perdidas") -> #REF!
D22: la llamdas en servicios tienenen que ser crm 37 y 50 para que se cuenten las llamdas conectadas y perdidas

Sheet Code
A1: CANAL | B1: PUERTO | E1: Campaña | F1: ENTIDAD | I1: llamdas | J1: coordenadas | R1: 50
A2: Puerto4D4 | B2: Chipera | E2: 90 | F2: Servicios | I2: FULL | J2: Conectadas | R2: 37
A3: Puerto26D4 | B3: Chipera | E3: 95 | F3: Admisiones | I3: NULL | J3: Perdidas | R3: 0
A4: Puerto24D4 | B4: Chipera | E4: 97 | F4: Admisiones
A5: Puerto6D4 | B5: Chipera | E5: 150 | F5: Admisiones
A6: Puerto18D4 | B6: Chipera
A7: Puerto28D4 | B7: Chipera
A8: Puerto30D4 | B8: Chipera
A9: Puerto25D4 | B9: Chipera
A10: Puerto15D4 | B10: Chipera
A11: Puerto11D4 | B11: Chipera
A12: Puerto20D4 | B12: Chipera
A13: Puerto12D4 | B13: Chipera
A14: Puerto8D4 | B14: Chipera
A15: Puerto32D4 | B15: Chipera
A16: Puerto27D4 | B16: Chipera
A17: Puerto23D4 | B17: Chipera
... A34: 100 | B34: Anura
